"C:\Users\evan\anaconda3\envs\l\lib\site-packages\eel\__main__.py" crashed at 2022-04-10T15:00:09+0200 (2022-04-10 15:00:09 W. Europe Daylight Time)

os.getcwd() => ('C:\\Users\\evan\\Documents\\GitHub\\Alpha67-Laucher-Zogmar\\electron '
                'laucher\\app')
os.environ => {'ALLUSERSPROFILE': 'C:\\ProgramData',
               'APPDATA': 'C:\\Users\\evan\\AppData\\Roaming',
               'COMMONPROGRAMFILES': 'C:\\Program Files\\Common Files',
               'COMMONPROGRAMFILES(X86)': 'C:\\Program Files (x86)\\Common Files',
               'COMMONPROGRAMW6432': 'C:\\Program Files\\Common Files',
               'COMPUTERNAME': 'DESKTOP-0LF1UAR',
               'COMSPEC': 'C:\\WINDOWS\\system32\\cmd.exe',
               'CONDA_DEFAULT_ENV': 'l',
               'CONDA_EXE': 'C:\\Users\\evan\\anaconda3\\Scripts\\conda.exe',
               'CONDA_PREFIX': 'C:\\Users\\evan\\anaconda3\\envs\\l',
               'CONDA_PREFIX_1': 'C:\\Users\\evan\\anaconda3',
               'CONDA_PROMPT_MODIFIER': '(l) ',
               'CONDA_PYTHON_EXE': 'C:\\Users\\evan\\anaconda3\\python.exe',
               'CONDA_SHLVL': '2',
               'DRIVERDATA': 'C:\\Windows\\System32\\Drivers\\DriverData',
               'HOMEDRIVE': 'C:',
               'HOMEPATH': '\\Users\\evan',
               'JAVA_HOME': 'C:\\Program Files\\Java\\jdk1.8.0_321',
               'LOCALAPPDATA': 'C:\\Users\\evan\\AppData\\Local',
               'LOGONSERVER': '\\\\DESKTOP-0LF1UAR',
               'NUMBER_OF_PROCESSORS': '6',
               'ONEDRIVE': 'C:\\Users\\evan\\OneDrive',
               'ONEDRIVECONSUMER': 'C:\\Users\\evan\\OneDrive',
               'OS': 'Windows_NT',
               'PATH': 'C:\\Users\\evan\\anaconda3\\envs\\l;C:\\Users\\evan\\anaconda3\\envs\\l\\Library\\mingw-w64\\bin;C:\\Users\\evan\\anaconda3\\envs\\l\\Library\\usr\\bin;C:\\Users\\evan\\anaconda3\\envs\\l\\Library\\bin;C:\\Users\\evan\\anaconda3\\envs\\l\\Scripts;C:\\Users\\evan\\anaconda3\\envs\\l\\bin;C:\\Users\\evan\\anaconda3\\condabin;C:\\Program '
                       'Files\\OpenJDK\\jdk-8.0.262.10-hotspot\\bin;C:\\Program Files '
                       '(x86)\\Common '
                       'Files\\Oracle\\Java\\javapath;C:\\WINDOWS\\system32;C:\\WINDOWS;C:\\WINDOWS\\System32\\Wbem;C:\\WINDOWS\\System32\\WindowsPowerShell\\v1.0;C:\\WINDOWS\\System32\\OpenSSH;C:\\Program '
                       'Files\\Git\\cmd;C:\\Program '
                       'Files\\Java\\jdk1.8.0_321\\bin;C:\\Users\\evan\\anaconda3;C:\\Users\\evan\\anaconda3\\Library\\mingw-w64\\bin;C:\\Users\\evan\\anaconda3\\Library\\usr\\bin;C:\\Users\\evan\\anaconda3\\Library\\bin;C:\\Users\\evan\\anaconda3\\Scripts;C:\\Users\\evan\\AppData\\Local\\Microsoft\\WindowsApps;C:\\Users\\evan\\AppData\\Local\\GitHubDesktop\\bin;C:\\Users\\evan\\AppData\\Local\\Programs\\Microsoft '
                       'VS Code\\bin',
               'PATHEXT': '.COM;.EXE;.BAT;.CMD;.VBS;.VBE;.JS;.JSE;.WSF;.WSH;.MSC',
               'PROCESSOR_ARCHITECTURE': 'AMD64',
               'PROCESSOR_IDENTIFIER': 'Intel64 Family 6 Model 158 Stepping 10, GenuineIntel',
               'PROCESSOR_LEVEL': '6',
               'PROCESSOR_REVISION': '9e0a',
               'PROGRAMDATA': 'C:\\ProgramData',
               'PROGRAMFILES': 'C:\\Program Files',
               'PROGRAMFILES(X86)': 'C:\\Program Files (x86)',
               'PROGRAMW6432': 'C:\\Program Files',
               'PROMPT': '(l) $P$G',
               'PSMODULEPATH': 'C:\\Program '
                               'Files\\WindowsPowerShell\\Modules;C:\\WINDOWS\\system32\\WindowsPowerShell\\v1.0\\Modules',
               'PUBLIC': 'C:\\Users\\Public',
               'SESSIONNAME': 'Console',
               'SYSTEMDRIVE': 'C:',
               'SYSTEMROOT': 'C:\\WINDOWS',
               'TEMP': 'C:\\Users\\evan\\AppData\\Local\\Temp',
               'TMP': 'C:\\Users\\evan\\AppData\\Local\\Temp',
               'USERDOMAIN': 'DESKTOP-0LF1UAR',
               'USERDOMAIN_ROAMINGPROFILE': 'DESKTOP-0LF1UAR',
               'USERNAME': 'evan',
               'USERPROFILE': 'C:\\Users\\evan',
               'WINDIR': 'C:\\WINDOWS',
               'ZES_ENABLE_SYSMAN': '1'}


===========================================================================

Traceback (most recent call last):
  File "C:\Users\evan\anaconda3\envs\l\lib\site-packages\PyInstaller\building\utils.py", line 430, in _make_clean_directory
    os.remove(path)
PermissionError: [WinError 5] Access is denied: 'C:\\Users\\evan\\Documents\\GitHub\\Alpha67-Laucher-Zogmar\\electron laucher\\app\\dist\\app'

During handling of the above exception, another exception occurred:

Traceback (most recent call last):
  File "C:\Users\evan\anaconda3\envs\l\lib\site-packages\eel\__main__.py", line 39, in <module>
    pyi.run(full_args)
  File "C:\Users\evan\anaconda3\envs\l\lib\site-packages\PyInstaller\__main__.py", line 124, in run
    run_build(pyi_config, spec_file, **vars(args))
  File "C:\Users\evan\anaconda3\envs\l\lib\site-packages\PyInstaller\__main__.py", line 58, in run_build
    PyInstaller.building.build_main.main(pyi_config, spec_file, **kwargs)
  File "C:\Users\evan\anaconda3\envs\l\lib\site-packages\PyInstaller\building\build_main.py", line 803, in main
    build(specfile, distpath, workpath, clean_build)
  File "C:\Users\evan\anaconda3\envs\l\lib\site-packages\PyInstaller\building\build_main.py", line 725, in build
    exec(code, spec_namespace)
  File "C:\Users\evan\Documents\GitHub\Alpha67-Laucher-Zogmar\electron laucher\app\app.spec", line 37, in <module>
    coll = COLLECT(exe,
  File "C:\Users\evan\anaconda3\envs\l\lib\site-packages\PyInstaller\building\api.py", line 847, in __init__
    self.__postinit__()
  File "C:\Users\evan\anaconda3\envs\l\lib\site-packages\PyInstaller\building\datastruct.py", line 155, in __postinit__
    self.assemble()
  File "C:\Users\evan\anaconda3\envs\l\lib\site-packages\PyInstaller\building\api.py", line 860, in assemble
    _make_clean_directory(self.name)
  File "C:\Users\evan\anaconda3\envs\l\lib\site-packages\PyInstaller\building\utils.py", line 432, in _make_clean_directory
    _rmtree(path)
  File "C:\Users\evan\anaconda3\envs\l\lib\site-packages\PyInstaller\building\utils.py", line 457, in _rmtree
    shutil.rmtree(path)
  File "C:\Users\evan\anaconda3\envs\l\lib\shutil.py", line 740, in rmtree
    return _rmtree_unsafe(path, onerror)
  File "C:\Users\evan\anaconda3\envs\l\lib\shutil.py", line 622, in _rmtree_unsafe
    onerror(os.rmdir, path, sys.exc_info())
  File "C:\Users\evan\anaconda3\envs\l\lib\shutil.py", line 620, in _rmtree_unsafe
    os.rmdir(path)
PermissionError: [WinError 32] The process cannot access the file because it is being used by another process: 'C:\\Users\\evan\\Documents\\GitHub\\Alpha67-Laucher-Zogmar\\electron laucher\\app\\dist\\app'

During handling of the above exception, another exception occurred:

Traceback (most recent call last):
  File "C:\Users\evan\anaconda3\envs\l\lib\site-packages\eel\__main__.py", line 44, in <module>
    5 + 's'
TypeError: unsupported operand type(s) for +: 'int' and 'str'

The above exception was the direct cause of the following exception:

Traceback (most recent call last):
  File "C:\Users\evan\anaconda3\envs\l\lib\runpy.py", line 194, in _run_module_as_main
    return _run_code(code, main_globals, None,
  File "C:\Users\evan\anaconda3\envs\l\lib\runpy.py", line 87, in _run_code
    exec(code, run_globals)
  File "C:\Users\evan\anaconda3\envs\l\lib\site-packages\eel\__main__.py", line 51, in <module>
    raise ValueError('exception raised') from cause
ValueError: exception raised


===========================================================================

Summary of exception variables:
__class__ => <class 'ValueError'>
__delattr__ => <method-wrapper '__delattr__' of ValueError object at 0x0000023C431F8A90>
__dict__ => {}
__dir__ => <built-in method __dir__ of ValueError object at 0x0000023C431F8A90>
__doc__ => 'Inappropriate argument value (of correct type).'
__eq__ => <method-wrapper '__eq__' of ValueError object at 0x0000023C431F8A90>
__format__ => <built-in method __format__ of ValueError object at 0x0000023C431F8A90>
__ge__ => <method-wrapper '__ge__' of ValueError object at 0x0000023C431F8A90>
__getattribute__ => <method-wrapper '__getattribute__' of ValueError object at 0x0000023C431F8A90>
__gt__ => <method-wrapper '__gt__' of ValueError object at 0x0000023C431F8A90>
__hash__ => <method-wrapper '__hash__' of ValueError object at 0x0000023C431F8A90>
__init__ => <method-wrapper '__init__' of ValueError object at 0x0000023C431F8A90>
__init_subclass__ => <built-in method __init_subclass__ of type object at 0x00007FFA03921360>
__le__ => <method-wrapper '__le__' of ValueError object at 0x0000023C431F8A90>
__lt__ => <method-wrapper '__lt__' of ValueError object at 0x0000023C431F8A90>
__ne__ => <method-wrapper '__ne__' of ValueError object at 0x0000023C431F8A90>
__new__ => <built-in method __new__ of type object at 0x00007FFA03921360>
__reduce__ => <built-in method __reduce__ of ValueError object at 0x0000023C431F8A90>
__reduce_ex__ => <built-in method __reduce_ex__ of ValueError object at 0x0000023C431F8A90>
__repr__ => <method-wrapper '__repr__' of ValueError object at 0x0000023C431F8A90>
__setattr__ => <method-wrapper '__setattr__' of ValueError object at 0x0000023C431F8A90>
__setstate__ => <built-in method __setstate__ of ValueError object at 0x0000023C431F8A90>
__sizeof__ => <built-in method __sizeof__ of ValueError object at 0x0000023C431F8A90>
__str__ => <method-wrapper '__str__' of ValueError object at 0x0000023C431F8A90>
__subclasshook__ => <built-in method __subclasshook__ of type object at 0x00007FFA03921360>
__suppress_context__ => True
__traceback__ => <traceback object at 0x0000023C43791780>
args => ('exception raised',)
with_traceback => <built-in method with_traceback of ValueError object at 0x0000023C431F8A90>
__cause__ =>
             __class__ => <class 'TypeError'>
             __delattr__ => <method-wrapper '__delattr__' of TypeError object at 0x0000023C4316B1D0>
             __dict__ => {}
             __dir__ => <built-in method __dir__ of TypeError object at 0x0000023C4316B1D0>
             __doc__ => 'Inappropriate argument type.'
             __eq__ => <method-wrapper '__eq__' of TypeError object at 0x0000023C4316B1D0>
             __format__ => <built-in method __format__ of TypeError object at 0x0000023C4316B1D0>
             __ge__ => <method-wrapper '__ge__' of TypeError object at 0x0000023C4316B1D0>
             __getattribute__ => <method-wrapper '__getattribute__' of TypeError object at 0x0000023C4316B1D0>
             __gt__ => <method-wrapper '__gt__' of TypeError object at 0x0000023C4316B1D0>
             __hash__ => <method-wrapper '__hash__' of TypeError object at 0x0000023C4316B1D0>
             __init__ => <method-wrapper '__init__' of TypeError object at 0x0000023C4316B1D0>
             __init_subclass__ => <built-in method __init_subclass__ of type object at 0x00007FFA0391E760>
             __le__ => <method-wrapper '__le__' of TypeError object at 0x0000023C4316B1D0>
             __lt__ => <method-wrapper '__lt__' of TypeError object at 0x0000023C4316B1D0>
             __ne__ => <method-wrapper '__ne__' of TypeError object at 0x0000023C4316B1D0>
             __new__ => <built-in method __new__ of type object at 0x00007FFA0391E760>
             __reduce__ => <built-in method __reduce__ of TypeError object at 0x0000023C4316B1D0>
             __reduce_ex__ => <built-in method __reduce_ex__ of TypeError object at 0x0000023C4316B1D0>
             __repr__ => <method-wrapper '__repr__' of TypeError object at 0x0000023C4316B1D0>
             __setattr__ => <method-wrapper '__setattr__' of TypeError object at 0x0000023C4316B1D0>
             __setstate__ => <built-in method __setstate__ of TypeError object at 0x0000023C4316B1D0>
             __sizeof__ => <built-in method __sizeof__ of TypeError object at 0x0000023C4316B1D0>
             __str__ => <method-wrapper '__str__' of TypeError object at 0x0000023C4316B1D0>
             __subclasshook__ => <built-in method __subclasshook__ of type object at 0x00007FFA0391E760>
             __suppress_context__ => False
             __traceback__ => <traceback object at 0x0000023C43791640>
             args => ("unsupported operand type(s) for +: 'int' and 'str'",)
             with_traceback => <built-in method with_traceback of TypeError object at 0x0000023C4316B1D0>
             __cause__ => None
             __context__ =>
